Workbook
Name Macro1: #REF!
Name Macro1: #REF!
Name Macro2: #REF!
Name Macro2: #REF!
Name Macro3: #REF!
Name Macro3: #REF!
Name Macro4: #REF!
Name Macro4: #REF!
Name Macro5: #REF!
Name Macro5: #REF!
Name Macro6: #REF!
Name Macro6: #REF!
Name Macro7: #REF!
Name Macro7: #REF!
Name Macro8: #REF!
Name Macro8: #REF!
Name Macro9: #REF!
Name Macro9: #REF!
Name Recover: #REF!
Name Recover: #REF!
Name TableName: "Dummy"

Sheet Data
D1: Country | E1: Series Name
E2: سال میلادی | F2: 1959 | G2: 1960 | H2: 1961 | I2: 1962 | J2: 1963 | K2: 1964 | L2: 1965 | M2: 1966 | N2: 1967 | O2: 1968 | P2: 1969 | Q2: 1970 | R2: 1971 | S2: 1972 | T2: 1973 | U2: 1974 | V2: 1975 | W2: 1976 | X2: 1977 | Y2: 1978 | Z2: 1979 | AA2: 1980 | AB2: 1981 | AC2: 1982 | AD2: 1983 | AE2: 1984 | AF2: 1985 | AG2: 1986 | AH2: 1987 | AI2: 1988 | AJ2: 1989 | AK2: 1990 | AL2: 1991 | AM2: 1992 | AN2: 1993 | AO2: 1994 | AP2: 1995 | AQ2: 1996 | AR2: 1997 | AS2: 1998 | AT2: 1999 | AU2: 2000 | AV2: 2001 | AW2: 2002 | AX2: 2003 | AY2: 2004 | AZ2: 2005 | BA2: 2006 | BB2: 2007 | BC2: 2008 | BD2: 2009 | BE2: 2010 | BF2: 2011 | BG2: 2012 | BH2: 2013 | BI2: 2014 | BJ2: 2015 | BK2: 2016 | BL2: 2017 | BM2: 2018 | BN2: 2019 | BO2: 2020 | BP2: 2021 | BQ2: 2022 | BR2: 2023 | BS2: 2024 | BT2: 2025 | BU2: پیش بینی 2026 | BV2: 2027 پیش بینی
E3: سال شمسی | F3: 1338 | G3: 1339 | H3: 1340 | I3: 1341 | J3: 1342 | K3: 1343 | L3: 1344 | M3: 1345 | N3: 1346 | O3: 1347 | P3: 1348 | Q3: 1349 | R3: 1350 | S3: 1351 | T3: 1352 | U3: 1353 | V3: 1354 | W3: 1355 | X3: 1356 | Y3: 1357 | Z3: 1358 | AA3: 1359 | AB3: 1360 | AC3: 1361 | AD3: 1362 | AE3: 1363 | AF3: 1364 | AG3: 1365 | AH3: 1366 | AI3: 1367 | AJ3: 1368 | AK3: 1369 | AL3: 1370 | AM3: 1371 | AN3: 1372 | AO3: 1373 | AP3: 1374 | AQ3: 1375 | AR3: 1376 | AS3: 1377 | AT3: 1378 | AU3: 1379 | AV3: 1380 | AW3: 1381 | AX3: 1382 | AY3: 1383 | AZ3: 1384 | BA3: 1385 | BB3: 1386 | BC3: 1387 | BD3: 1388 | BE3: 1389 | BF3: 1390 | BG3: 1391 | BH3: 1392 | BI3: 1393 | BJ3: 1394 | BK3: 1395 | BL3: 1396 | BM3: 1397 | BN3: 1398 | BO3: 1399 | BP3: 1400 | BQ3: 1401 | BR3: 1402 | BS3: 1403 | BT3: 1404 | BU3: پیش بینی 1405 | BV3: پیش بینی 1406
D4: IRN | E4: شاخص قیمت مصرف کننده (بانک مرکزی) | F4: 0.1 | G4: 0.1 | H4: 0.1 | I4: 0.1 | J4: 0.1 | K4: 0.1 | L4: 0.1 | M4: 0.1 | N4: 0.1 | O4: 0.1 | P4: 0.1 | Q4: 0.1 | R4: 0.1 | S4: 0.2 | T4: 0.2 | U4: 0.2 | V4: 0.2 | W4: 0.3 | X4: 0.3 | Y4: 0.3 | Z4: 0.4 | AA4: 0.5 | AB4: 0.6 | AC4: 0.7 | AD4: 0.8 | AE4: 0.9 | AF4: 0.9 | AG4: 1.2 | AH4: 1.5 | AI4: 1.9 | AJ4: 2.2 | AK4: 2.45344 | AL4: 2.95856 | AM4: 3.68016 | AN4: 4.51 | AO4: 6.09752 | AP4: 9.09216 | AQ4: 11.1848 | AR4: 13.1 | AS4: 15.5 | AT4: 18.6 | AU4: 21 | AV4: 23.4 | AW4: 27.1 | AX4: 31.3 | AY4: 36.1 | AZ4: 39.8 | BA4: 44.6 | BB4: 52.7 | BC4: 66.1 | BD4: 73.2 | BE4: 82.3 | BF4: 100 | BG4: 130.5 | BH4: 175.9 | BI4: 203.2 | BJ4: 227.5 | BK4: 248 | BL4: 272.056 | BM4: 356.72733 | BN4: 503.812 | BO4: 741.16867 | BP4: 1083.8633 | BQ4: 1587.758 | BR4: 2233.9755 | BS4: =BR4*(1+BS5%) -> 2957.7836 | BT4: =BS4*(1+BT5%) -> 4229.6305 | BU4: =BT4*(1+BU5%) -> 6555.9273 | BV4: 9555
D5: IRN | E5: تورم (بانک مرکزی) | F5: 13 | G5: 7.9 | H5: 1.6 | I5: 0.9 | J5: 1 | K5: 4.5 | L5: 0.3 | M5: 0.8 | N5: 0.8 | O5: 1.5 | P5: 3.6 | Q5: 1.5 | R5: 5.5 | S5: 6.3 | T5: 11.2 | U5: 15.5 | V5: 9.9 | W5: 16.6 | X5: 25.1 | Y5: 10 | Z5: 11.4 | AA5: 23.5 | AB5: 22.8 | AC5: 19.2 | AD5: 14.8 | AE5: 10.4 | AF5: 6.9 | AG5: 23.7 | AH5: 27.7 | AI5: 28.9 | AJ5: 17.4 | AK5: 9 | AL5: 20.7 | AM5: 24.4 | AN5: 22.9 | AO5: 35.2 | AP5: 49.4 | AQ5: 23.2 | AR5: 17.3 | AS5: 18.1 | AT5: 20.1 | AU5: 12.6 | AV5: 11.4 | AW5: 15.8 | AX5: 15.6 | AY5: 15.2 | AZ5: 10.4 | BA5: 11.9 | BB5: 18.4 | BC5: 25.4 | BD5: 10.8 | BE5: 12.4 | BF5: 21.5 | BG5: 30.5 | BH5: 34.7 | BI5: 15.6 | BJ5: 11.9 | BK5: 9 | BL5: 9.6 | BM5: 31.2 | BN5: 41.2 | BO5: 47.1 | BP5: 46.2 | BQ5: 46.5 | BR5: 40.7 | BS5: 32.4 | BT5: 43 | BU5: 55 | BV5: 67
D6: IRN | E6: شاخص قیمت مصرف کننده (مرکز امار) | G6: 0.14143422 | H6: 0.14590717 | I6: 0.14695963 | J6: 0.1475061 | K6: 0.1531327 | L6: 0.15643175 | M6: 0.15582457 | N6: 0.15831404 | O6: 0.15940697 | P6: 0.16513478 | Q6: 0.16788736 | R6: 0.17493074 | S6: 0.18612323 | T6: 0.20439957 | U6: 0.23352434 | V6: 0.26360036 | W6: 0.29327159 | X6: 0.37329891 | Y6: 0.4170569 | Z6: 0.46079464 | AA6: 0.55592069 | AB6: 0.69047345 | AC6: 0.81952105 | AD6: 0.98129605 | AE6: 1.1043527 | AF6: 1.1528265 | AG6: 1.365281 | AH6: 1.7553613 | AI6: 2.2586345 | AJ6: 2.7634314 | AK6: 2.974217 | AL6: 3.4836578 | AM6: 4.3827105 | AN6: 5.3119605 | AO6: 6.9824142 | AP6: 10.449601 | AQ6: 13.473438 | AR6: 15.810975 | AS6: 18.635785 | AT6: 22.376119 | AU6: 25.615454 | AV6: 28.503403 | AW6: 32.589632 | AX6: 37.956497 | AY6: 43.559448 | AZ6: 49.410841 | BA6: 54.35978 | BB6: 63.786332 | BC6: 79.994763 | BD6: 90.835297 | BE6: 100 | BF6: 126.29339 | BG6: 160.71694 | BH6: 219.54421 | BI6: 256.00294 | BJ6: 287.96409 | BK6: 308.82832 | BL6: 333.67332 | BM6: 393.78163 | BN6: 550.92943 | BO6: 719.48154 | BP6: 1031.6575 | BQ6: =BP6+BP6*(BQ7%) -> 1504.1566 | BR6: =BQ6+BQ6*(BR7%) -> 2105.8193 | BS6: =BR6+BR6*(BS7%) -> 2800.7397 | BT6: =BS6+BS6*(BT7%) -> 3865.0207 | BU6: =BT6+BT6*(BU7%) -> 5604.2801 | BV6: 5690 | BX6: Consumer price index (2010 = 100)
D7: IRN | E7: تورم (مرکز امار) | G7: 9.8224108 | H7: 3.1625644 | I7: 0.72132057 | J7: 0.37184961 | K7: 3.8144896 | L7: 2.1543748 | M7: -0.38814853 | N7: 1.5976101 | O7: 0.69036052 | P7: 3.5931945 | Q7: 1.6668709 | R7: 4.1952984 | S7: 6.3982414 | T7: 9.8194867 | U7: 14.248936 | V7: 12.879182 | W7: 11.256143 | X7: 27.287785 | Y7: 11.721969 | Z7: 10.487237 | AA7: 20.643914 | AB7: 24.20359 | AC7: 18.689726 | AD7: 19.740189 | AE7: 12.540219 | AF7: 4.389341 | AG7: 18.429003 | AH7: 28.571429 | AI7: 28.670635 | AJ7: 22.349653 | AK7: 7.6276749 | AL7: 17.128568 | AM7: 25.807723 | AN7: 21.202631 | AO7: 31.447028 | AP7: 49.655986 | AQ7: 28.937344 | AR7: 17.349226 | AS7: 17.866134 | AT7: 20.070708 | AU7: 14.476751 | AV7: 11.274247 | AW7: 14.335934 | AX7: 16.468012 | AY7: 14.761509 | AZ7: 13.433118 | BA7: 10.015898 | BB7: 17.34104 | BC7: 25.410509 | BD7: 13.551555 | BE7: 10.089363 | BF7: 26.293386 | BG7: 27.256813 | BH7: 36.603036 | BI7: 16.606553 | BJ7: 12.484682 | BK7: 7.2454255 | BL7: 8.0449244 | BM7: 18.014118 | BN7: 39.907346 | BO7: 30.594139 | BP7: 43.389016 | BQ7: 45.8 | BR7: 40 | BS7: 33 | BT7: 38 | BU7: 45 | BV7: 73 | BW7: تورم | BX7: Inflation, consumer prices (annual %)
D8: IRN | E8: نقدینگی (همت) | G8: 0.005207 | H8: 0.005714 | I8: 0.007181 | J8: 0.00857 | K8: 0.009944 | L8: 0.011431 | M8: 0.013061 | N8: 0.015562 | O8: 0.017977 | P8: 0.021166 | Q8: 0.024968 | R8: 0.030962 | S8: 0.041877 | T8: 0.05 | U8: 0.08 | V8: 0.11 | W8: 0.16 | X8: 0.21 | Y8: 0.26 | Z8: 0.36 | AA8: 0.45 | AB8: 0.52 | AC8: 0.64 | AD8: 0.75 | AE8: 0.8 | AF8: 0.9 | AG8: 1.07 | AH8: 1.27 | AI8: 1.57 | AJ8: 1.88 | AK8: 2.3 | AL8: 2.86 | AM8: 3.59 | AN8: 4.81 | AO8: 6.18 | AP8: 8.51 | AQ8: 11.66 | AR8: 13.43 | AS8: 16.04 | AT8: 19.27 | AU8: 24.91 | AV8: 32.1 | AW8: 41.75 | AX8: 52.66 | AY8: 68.59 | AZ8: 92.1 | BA8: 128.42 | BB8: 164.03 | BC8: 190.14 | BD8: 235.59 | BE8: 294.89 | BF8: 354.26 | BG8: 460.69 | BH8: 639.55 | BI8: 782.38 | BJ8: 1017.28 | BK8: 1253.39 | BL8: 1529.98 | BM8: 1882.89 | BN8: 2472.15 | BO8: 3476.17 | BP8: 4832.44 | BQ8: 6337.68 | BR8: 7877.45 | BS8: =BR8*(1+BS9%) -> 10083.136 | BT8: 14787.967 | BU8: 21083.105 | BV8: 30058.467 | BX8: Broad money (current LCU)
D9: IRN | E9: رشد نقدینگی | G9: .. | H9: =(H8/G8-1)*100 -> 9.7368926 | I9: 25.673784 | J9: 19.34271 | K9: 16.032672 | L9: 14.953741 | M9: 14.25947 | N9: 19.14861 | O9: 15.518571 | P9: 17.739334 | Q9: 17.96277 | R9: 24.006729 | S9: 35.252891 | T9: 30.291091 | U9: 56.389961 | V9: 41.402296 | W9: 39.109559 | X9: 31.597113 | Y9: 22.966142 | Z9: 37.671605 | AA9: 26.988732 | AB9: 16.14871 | AC9: 22.81469 | AD9: 16.851976 | AE9: 6.0217715 | AF9: 12.993762 | AG9: 19.112207 | AH9: 18.144853 | AI9: 23.834483 | AJ9: 19.542186 | AK9: 22.482443 | AL9: 24.636583 | AM9: 25.281189 | AN9: 34.207885 | AO9: 28.480316 | AP9: 37.559343 | AQ9: 37.004333 | AR9: 15.21519 | AS9: 19.447405 | AT9: 20.129301 | AU9: 29.281091 | AV9: 28.841234 | AW9: 30.087086 | AX9: 26.123624 | AY9: 30.245326 | AZ9: 34.285384 | BA9: 39.432394 | BB9: 27.72884 | BC9: 15.916242 | BD9: 23.905082 | BE9: 25.170332 | BF9: 20.132351 | BG9: 30.045685 | BH9: 38.823395 | BI9: 22.333547 | BJ9: 30.022978 | BK9: 23.209932 | BL9: 22.067353 | BM9: 23.066315 | BN9: 31.295509 | BO9: 40.613231 | BP9: 39.016216 | BQ9: 35.235204 | BR9: 27.423193 | BS9: 28 | BT9: 36 | BU9: 42 | BV9: 42 | BW9: رشد نقدینگی | BX9: Broad money growth (annual %)
D10: IRN | E10: رشد اقتصادی | G10: .. | H10: 10.390918 | I10: 7.9092679 | J10: 7.0420752 | K10: 8.4752282 | L10: 17.035712 | M10: 11.502407 | N10: 11.252803 | O10: 14.404183 | P10: 15.516659 | Q10: 10.927602 | R10: 13.701583 | S10: 14.499016 | T10: 7.4416816 | U10: 5.8010508 | V10: -0.32621624 | W10: 18.260436 | X10: -2.7735777 | Y10: -12.840857 | Z10: -12.02076 | AA10: -21.599649 | AB10: -5.6967872 | AC10: 23.171246 | AD10: 11.086717 | AE10: -7.1398505 | AF10: 1.8676499 | AG10: -9.7849056 | AH10: -0.17210769 | AI10: -6.0819966 | AJ10: 6.1321157 | AK10: 13.594926 | AL10: 12.716148 | AM10: 3.2979819 | AN10: -1.4710115 | AO10: -1.6982861 | AP10: 2.4010446 | AQ10: 6.350526 | AR10: 1.3503993 | AS10: 2.0800118 | AT10: 2.0026962 | AU10: 5.8455275 | AV10: 2.3921727 | AW10: 8.0788293 | AX10: 8.6392984 | AY10: 4.336666 | AZ10: 3.1898041 | BA10: 4.9997953 | BB10: 8.1557735 | BC10: 0.25085655 | BD10: 1.0073855 | BE10: 5.7979383 | BF10: 2.6457179 | BG10: -3.7471714 | BH10: -1.5219792 | BI10: 4.9847751 | BJ10: -1.4248849 | BK10: 8.8150866 | BL10: 2.7585052 | BM10: -2.2538636 | BN10: -2.6582067 | BO10: 3.3302885 | BP10: 4.7197777 | BQ10: 2.7491661 | BR10: 5.5 | BS10: 3 | BT10: 0.5 | BU10: -6.5 | BV10: -3.2 | BW10: رشد اقتصادی | BX10: GDP growth (annual %)
D11: IRN | E11: تولید ناخالص داخلی (GDP)- دلار جاری امریکا | G11: 4.1991344 | H11: 4.4269491 | I11: 4.6935664 | J11: 4.928628 | K11: 5.3798456 | L11: 6.1973199 | M11: 6.7899387 | N11: 7.5553837 | O11: 8.623173 | P11: 9.7430896 | Q11: 10.976245 | R11: 13.731803 | S11: 17.153463 | T11: 27.081698 | U11: 46.209092 | V11: 51.776222 | W11: 68.055295 | X11: 80.600123 | Y11: 77.994317 | Z11: 90.391877 | AA11: 94.362276 | AB11: 100.49931 | AC11: 125.94876 | AD11: 156.36516 | AE11: 162.27673 | AF11: 180.18363 | AG11: 209.09456 | AH11: 134.01 | AI11: 123.05786 | AJ11: 120.49636 | AK11: 124.81326 | AL11: 131.63766 | AM11: 119.76869 | AN11: 63.743623 | AO11: 71.841461 | AP11: 96.419226 | AQ11: 120.40393 | AR11: 113.91916 | AS11: 110.27691 | AT11: 113.84845 | AU11: 109.59171 | AV11: 126.87875 | AW11: 128.62692 | AX11: 151.91122 | AY11: 187.75457 | AZ11: 224.97037 | BA11: 265.60219 | BB11: 349.73659 | BC11: 406.07095 | BD11: 414.05909 | BE11: 487.06957 | BF11: 629.08226 | BG11: 644.01932 | BH11: 500.39984 | BI11: 462.28479 | BJ11: 409.19169 | BK11: 478.61806 | BL11: 510.23989 | BM11: 411.9033 | BN11: 347.9884 | BO11: 280.93433 | BP11: 407.35069 | BQ11: 422.66226 | BR11: 457.51048 | BS11: 475.25209 | BT11: 499 | BU11: =(BT11*0.04)+BT11 -> 518.96 | BV11: =(BU11*0.04)+BU11 -> 539.7184 | BX11: GDP (constant 2015 US$)
D12: IRN | E12: صادرات نفتی (میلیون دلار) | R12: =S12*0.9 -> 6737.58 | S12: =T12*0.9 -> 7486.2 | T12: =T94 -> 8318 | U12: =U94 -> 21014 | V12: =V94 -> 20034 | W12: =W94 -> 24179 | X12: =X94 -> 23451 | Y12: =Y94 -> 15660 | Z12: =Z94 -> 24158 | AA12: =AA94 -> 11648 | ... AQ12: =AQ94 -> 19271 | AR12: =AR95 -> 15931.892 | AS12: =AS95 -> 10659.173 | AT12: =AT95 -> 17976.917 | AU12: =AU95 -> 24955.164 | AV12: =AV95 -> 20152.595 | AW12: =AW95 -> 23784.948 | AX12: =AX95 -> 28406.995 | AY12: =AY95 -> 37448.16 | ... BR12: =BR95 -> 56796.41 | BS12: =BR12-7000 -> 49796.41 | BT12: =BS12*0.8 -> 39837.128 | BU12: 46000 | BV12: 41000
D13: USA | E13: شاخص قیمت مصرف کننده | G13: 13.563061 | H13: 13.708284 | I13: 13.872615 | J13: 14.04459 | K13: 14.224207 | L13: 14.449685 | M13: 14.885354 | N13: 15.298093 | O13: 15.951596 | P13: 16.822934 | Q13: 17.8051 | R13: 18.569431 | S13: 19.177075 | T13: 20.361789 | U13: 22.612745 | V13: 24.680261 | W13: 26.098096 | X13: 27.794912 | Y13: 29.915931 | Z13: 33.282811 | AA13: 37.792366 | AB13: 41.6981 | AC13: 44.254788 | AD13: 45.676445 | AE13: 47.640776 | AF13: 49.329949 | AG13: 50.266255 | AH13: 52.108294 | AI13: 54.233135 | AJ13: 56.85097 | AK13: 59.91976 | AL13: 62.457341 | AM13: 64.349061 | AN13: 66.248425 | AO13: 67.975813 | AP13: 69.88282 | AQ13: 71.931229 | AR13: 73.612758 | AS13: 74.755433 | AT13: 76.391102 | AU13: 78.970721 | AV13: 81.202568 | AW13: 82.490467 | AX13: 84.363079 | AY13: 86.621678 | AZ13: 89.560532 | BA13: 92.449705 | BB13: 95.086992 | BC13: 98.737477 | BD13: 98.38642 | BE13: 100 | BF13: 103.15684 | BG13: 105.2915 | BH13: 106.83385 | BI13: 108.56693 | BJ13: 108.69572 | BK13: 110.06701 | BL13: 112.41156 | BM13: 115.1573 | BN13: 117.2442 | BO13: 118.6905 | BP13: 124.26641 | BQ13: 134.21121 | BR13: =BQ13+(BR14%*BQ13) -> 138.9086 | BS13: =BR13+(BS14%*BR13) -> 142.38131 | BT13: =BS13+(BT14%*BS13) -> 145.65608 | BU13: =BT13+(BU14%*BT13) -> 151.20558 | BV13: 157.04 | BX13: Consumer price index (2010 = 100)
D14: USA | E14: تورم | G14: 1.457976 | H14: 1.0707241 | I14: 1.1987733 | J14: 1.2396694 | K14: 1.2789116 | L14: 1.5851693 | M14: 3.0150754 | N14: 2.7727856 | O14: 4.2717962 | P14: 5.4623862 | Q14: 5.8382553 | R14: 4.2927667 | S14: 3.2722782 | T14: 6.1777601 | U14: 11.054805 | V14: 9.1431469 | W14: 5.7448126 | X14: 6.501684 | Y14: 7.6309638 | Z14: 11.254471 | AA14: 13.549202 | AB14: 10.334715 | AC14: 6.131427 | AD14: 3.2124352 | AE14: 4.3005355 | AF14: 3.5456442 | AG14: 1.8980477 | AH14: 3.6645632 | AI14: 4.0777411 | AJ14: 4.827003 | AK14: 5.3979564 | AL14: 4.234964 | AM14: 3.0288197 | AN14: 2.951657 | AO14: 2.6074416 | AP14: 2.8054197 | AQ14: 2.9312042 | AR14: 2.3376899 | AS14: 1.5522791 | AT14: 2.1880272 | AU14: 3.3768573 | AV14: 2.8261711 | AW14: 1.5860316 | AX14: 2.270095 | AY14: 2.6772367 | AZ14: 3.3927468 | BA14: 3.2259441 | BB14: 2.8526725 | BC14: 3.8391003 | BD14: -0.35554627 | BE14: 1.6400434 | BF14: 3.1568416 | BG14: 2.0693373 | BH14: 1.4648327 | BI14: 1.622223 | BJ14: 0.11862714 | BK14: 1.2615832 | BL14: 2.13011 | BM14: 2.4425833 | BN14: 1.8122101 | BO14: 1.2335844 | BP14: 4.6978589 | BQ14: 8.0027998 | BR14: 3.5 | BS14: 2.5 | BT14: 2.3 | BU14: 3.81 | BV14: 3 | BW14: تورم | BX14: Inflation, consumer prices (annual %)
D15: USA | E15: نقدینگی- میلیارد دلار | G15: 326.239 | H15: 352.973 | I15: 384.507 | J15: 420.332 | K15: 458.295 | L15: 497.807 | M15: 521.303 | N15: 574.88 | O15: 625.349 | P15: 631.342 | Q15: 701.958 | R15: 799.918 | S15: 908.63 | T15: 1001.092 | U15: 1079.685 | V15: 1189.58 | W15: 1311.016 | X15: 1468.795 | Y15: 1634.343 | Z15: 1794.383 | AA15: 1986.011 | AB15: 2225.612 | AC15: 2448.89 | AD15: 2651.444 | AE15: 2983.758 | AF15: 3231.204 | AG15: 3534.144 | AH15: 3677.79 | AI15: 3927.548 | AJ15: 4136.39 | AK15: 4247.161 | AL15: 4310.89 | AM15: 4304.287 | AN15: 4329.959 | AO15: 4347.481 | AP15: 4646.119 | AQ15: 5011.559 | AR15: 5412.659 | AS15: 5932.377 | AT15: 6496.459 | AU15: 7023.352 | AV15: 7580.5002 | AW15: 7917.9987 | AX15: 8266.6831 | AY15: 8741.3599 | AZ15: 9447.0941 | BA15: 10297.599 | BB15: 11503.808 | BC15: 12444.256 | BD15: 13130.258 | BE15: 12768.869 | BF15: 13622.258 | BG15: 14289.979 | BH15: 14933.187 | BI15: 15706.487 | BJ15: 16200.148 | BK15: 16823.762 | BL15: 17631.631 | BM15: 18342.26 | BN15: 19881.524 | BO15: 23301.048 | BP15: 27248.9 | BQ15: 21289.8 | BR15: 19509.606 | BS15: 20875.278 | BT15: =BS15*(1+BT16%) -> 21919.042 | BU15: =BT15*(1+BU16%) -> 22920.743 | BV15: =BU15*(1+BV16%) -> 23968.221 | BX15: Broad money (current LCU)
D16: USA | E16: رشد نقدینگی | G16: .. | H16: 8.1946058 | I16: 8.9338278 | J16: 9.3171256 | K16: 9.0316702 | L16: 8.6215211 | M16: 4.7199015 | N16: 10.277516 | O16: 8.7790495 | P16: 0.95834486 | Q16: 11.185063 | R16: 13.955251 | S16: 13.590393 | T16: 10.175979 | U16: 7.850727 | V16: 10.178432 | W16: 10.208309 | X16: 12.034865 | Y16: 11.271008 | Z16: 9.7923141 | AA16: 10.679325 | AB16: 12.064435 | AC16: 10.032207 | AD16: 8.2712576 | AE16: 12.533321 | AF16: 8.2930988 | AG16: 9.3754526 | AH16: 4.0645203 | AI16: 6.7909805 | AJ16: 5.3173634 | AK16: 2.6779632 | AL16: 1.5005082 | AM16: -0.15317023 | AN16: 0.59642863 | AO16: 0.40466896 | AP16: 6.8692192 | AQ16: 7.8654895 | AR16: 8.0034975 | AS16: 9.6018981 | AT16: 9.5085326 | AU16: 8.1104645 | AV16: 7.9327962 | AW16: 4.4521933 | AX16: 4.4036937 | AY16: 5.7420457 | AZ16: 8.0735061 | BA16: 9.0028239 | BB16: 11.713489 | BC16: 8.1751045 | BD16: 5.5126012 | BE16: -2.7523399 | BF16: 6.6833552 | BG16: 4.9016934 | BH16: 4.5011135 | BI16: 5.1783996 | BJ16: 3.1430398 | BK16: 3.8494318 | BL16: 4.801954 | BM16: 4.03042 | BN16: 8.391899 | BO16: 17.199506 | BP16: 16.942808 | BQ16: =(BQ15/BP15-1)*100 -> -21.869138 | BR16: =(BR15/BQ15-1)*100 -> -8.3617225 | BS16: 7 | BT16: 5 | BU16: 4.57 | BV16: 4.57 | BW16: رشد نقدینگی | BX16: Broad money growth (annual %)
D17: USA | E17: رشد اقتصادی | G17: .. | H17: 2.3 | I17: 6.1 | J17: 4.4 | K17: 5.8 | L17: 6.4 | M17: 6.5 | N17: 2.5 | O17: 4.8 | P17: 3.1 | Q17: -0.28349126 | R17: 3.2933516 | S17: 5.2589074 | T17: 5.6457226 | U17: -0.54055165 | V17: -0.20545607 | W17: 5.3881393 | X17: 4.6241531 | Y17: 5.535305 | Z17: 3.1661453 | AA17: -0.25674967 | AB17: 2.5377193 | AC17: -1.8028874 | AD17: 4.5839134 | AE17: 7.2366332 | AF17: 4.1696562 | AG17: 3.462646 | AH17: 3.459252 | AI17: 4.1770613 | AJ17: 3.6726481 | AK17: 1.885965 | AL17: -0.10826479 | AM17: 3.5224405 | AN17: 2.7517811 | AO17: 4.0287933 | AP17: 2.6842173 | AQ17: 3.7725655 | AR17: 4.4471749 | AS17: 4.4813944 | AT17: 4.794499 | AU17: 4.0771595 | AV17: 0.95433873 | AW17: 1.6959429 | AX17: 2.7962091 | AY17: 3.8525526 | AZ17: 3.4832203 | BA17: 2.7828106 | BB17: 2.0105076 | BC17: 0.12218844 | BD17: -2.5998884 | BE17: 2.7088567 | BF17: 1.549895 | BG17: 2.2806876 | BH17: 1.8418754 | BI17: 2.2877759 | BJ17: 2.7063696 | BK17: 1.6674721 | BL17: 2.2419212 | BM17: 2.9453848 | BN17: 2.2944391 | BO17: -2.7678025 | BP17: 5.9454848 | BQ17: 2.0615931 | BR17: 3 | BS17: 2.5 | BT17: 2.1 | BU17: 1.1 | BV17: 3.1 | BW17: رشد اقتصادی | BX17: GDP growth (annual %)
D18: USA | E18: تولید ناخالص داخلی (GDP)_دلار ثابت 2015_میلیارد دلار | G18: 3457.188 | H18: 3536.7034 | I18: 3752.4423 | J18: 3917.5497 | K18: 4144.7676 | L18: 4410.0327 | M18: 4696.6849 | N18: 4814.102 | O18: 5045.1789 | P18: 5201.5794 | Q18: 5186.8334 | R18: 5357.6541 | S18: 5639.4081 | T18: 5957.7935 | U18: 5925.5885 | V18: 5913.414 | W18: 6232.037 | X18: 6520.216 | Y18: 6881.1298 | Z18: 7098.9964 | AA18: 7080.7697 | AB18: 7260.4598 | AC18: 7129.5619 | AD18: 7456.3748 | AE18: 7995.9653 | AF18: 8329.3695 | AG18: 8617.7861 | AH18: 8915.8971 | AI18: 9288.3195 | AJ18: 9629.4468 | AK18: 9811.0548 | AL18: 9800.4329 | AM18: 10145.647 | AN18: 10424.833 | AO18: 10844.828 | AP18: 11135.927 | AQ18: 11556.037 | AR18: 12069.954 | AS18: 12610.857 | AT18: 13215.484 | AU18: 13754.3 | AV18: 13885.563 | AW18: 14121.054 | AX18: 14515.908 | AY18: 15075.141 | AZ18: 15600.242 | BA18: 16034.367 | BB18: 16356.739 | BC18: 16376.725 | BD18: 15950.949 | BE18: 16383.037 | BF18: 16636.957 | BG18: 17016.394 | BH18: 17329.815 | BI18: 17726.282 | BJ18: 18206.021 | BK18: 18509.601 | BL18: 18924.572 | BM18: 19481.973 | BN18: 19928.975 | BO18: 19377.381 | BP18: 20529.46 | BQ18: 20952.694 | BR18: 21581.274 | BS18: 22120.806 | BT18: =BS18*(1+BT17%) -> 22585.343 | BU18: =BT18*(1+BU17%) -> 22833.782 | BV18: =BU18*(1+BV17%) -> 23541.629 | BX18: GDP (constant 2015 US$)
E23: سال میلادی | F23: 1959 | G23: 1960 | H23: 1961 | I23: 1962 | J23: 1963 | K23: 1964 | L23: 1965 | M23: 1966 | N23: 1967 | O23: 1968 | P23: 1969 | Q23: 1970 | R23: 1971 | S23: 1972 | T23: 1973 | U23: 1974 | V23: 1975 | W23: 1976 | X23: 1977 | Y23: 1978 | Z23: 1979 | AA23: 1980 | AB23: 1981 | AC23: 1982 | AD23: 1983 | AE23: 1984 | AF23: 1985 | AG23: 1986 | AH23: 1987 | AI23: 1988 | AJ23: 1989 | AK23: 1990 | AL23: 1991 | AM23: 1992 | AN23: 1993 | AO23: 1994 | AP23: 1995 | AQ23: 1996 | AR23: 1997 | AS23: 1998 | AT23: 1999 | AU23: 2000 | AV23: 2001 | AW23: 2002 | AX23: 2003 | AY23: 2004 | AZ23: 2005 | BA23: 2006 | BB23: 2007 | BC23: 2008 | BD23: 2009 | BE23: 2010 | BF23: 2011 | BG23: 2012 | BH23: 2013 | BI23: 2014 | BJ23: 2015 | BK23: 2016 | BL23: 2017 | BM23: 2018 | BN23: 2019 | BO23: 2020 | BP23: 2021 | BQ23: 2022 | BR23: 2023 | BS23: 2024 | BT23: 2025 | BU23: 2026 پیش بینی | BV23: 2027 پیش بینی | BZ23: =13534*((1+3%)^(3))-1 -> 14787.967
E24: سال شمسی | F24: 1338 | G24: 1339 | H24: 1340 | I24: 1341 | J24: 1342 | K24: 1343 | L24: 1344 | M24: 1345 | N24: 1346 | O24: 1347 | P24: 1348 | Q24: 1349 | R24: 1350 | S24: 1351 | T24: 1352 | U24: 1353 | V24: 1354 | W24: 1355 | X24: 1356 | Y24: 1357 | Z24: 1358 | AA24: 1359 | AB24: 1360 | AC24: 1361 | AD24: 1362 | AE24: 1363 | AF24: 1364 | AG24: 1365 | AH24: 1366 | AI24: 1367 | AJ24: 1368 | AK24: 1369 | AL24: 1370 | AM24: 1371 | AN24: 1372 | AO24: 1373 | AP24: 1374 | AQ24: 1375 | AR24: 1376 | AS24: 1377 | AT24: 1378 | AU24: 1379 | AV24: 1380 | AW24: 1381 | AX24: 1382 | AY24: 1383 | AZ24: 1384 | BA24: 1385 | BB24: 1386 | BC24: 1387 | BD24: 1388 | BE24: 1389 | BF24: 1390 | BG24: 1391 | BH24: 1392 | BI24: 1393 | BJ24: 1394 | BK24: 1395 | BL24: 1396 | BM24: 1397 | BN24: 1398 | BO24: 1399 | BP24: 1400 | BQ24: 1401 | BR24: 1402 | BS24: 1403 | BT24: 1404 | BU24: پیش بینی 1405 | BV24: پیش بینی 1406 | BZ24: =BZ23*((1+3%)^(12))-1 -> 21083.105
E25: نرخ ارز بازار آزاد (ریال) | F25: 76 | G25: 76 | H25: 76 | I25: 76 | J25: 76 | K25: 76 | L25: 76 | M25: 76 | N25: 76 | O25: 76 | P25: 76 | Q25: 76 | R25: 76 | S25: 69 | T25: 68 | U25: 68 | V25: 68 | W25: 71 | X25: 71 | Y25: 100 | Z25: 141 | AA25: 200 | AB25: 270 | AC25: 350 | AD25: 450 | AE25: 580 | AF25: 614 | AG25: 742 | AH25: 991 | AI25: 966 | AJ25: 1207.1 | AK25: 1412.3 | AL25: 1420.2 | AM25: 1498 | AN25: 1806 | AO25: 2635 | AP25: 4036 | AQ25: 4446 | AR25: 4782 | AS25: 6468 | AT25: 8634 | AU25: 8131 | AV25: 7925 | AW25: 7991 | AX25: 8323 | AY25: 8747 | AZ25: 9042 | BA25: 9226 | BB25: 9357 | BC25: 9667 | BD25: 9979 | BE25: 10601 | BF25: 13568 | BG25: 26059 | BH25: 31839 | BI25: 32801 | BJ25: 34501 | BK25: 36440 | BL25: 40453 | BM25: 103378 | BN25: 129185 | BO25: 228809 | BP25: 259476 | BQ25: 349266 | BR25: 517807.6 | BS25: 690000 | BT25: =BT45 -> 1000643.6 | BU25: =BU45 -> 1494073.4 | BV25: =BV45 -> 2096650.4 | BZ25: =BZ24*((1+3%)^(12))-1 -> 30058.467
E26: نرخ ارز رسمی (ریال) | F26: 76 | G26: 76 | H26: 76 | I26: 76 | J26: 76 | K26: 76 | L26: 76 | M26: 76 | N26: 76 | O26: 76 | P26: 76 | Q26: 76 | R26: 76 | S26: 69 | T26: 68 | U26: 68 | V26: 68 | W26: 71 | X26: 71 | Y26: 70 | Z26: 70 | AA26: 71 | AB26: 80 | AC26: 84 | AD26: 87 | AE26: 92 | AF26: 88 | AG26: 77 | AH26: 70 | AI26: 69 | AJ26: 72 | AK26: 66.9 | AL26: 67.8 | AM26: 1458.5 | AN26: 1653 | AO26: 1750 | AP26: 1750 | AQ26: 1754 | AR26: 1755 | AS26: 1755 | AT26: 1755 | AU26: 1755 | AV26: 1755 | AW26: 7958 | AX26: 8282 | AY26: 8719 | AZ26: 9023 | BA26: 9195 | BB26: 9285 | BC26: 9574 | BD26: 9920 | BE26: 10339 | BF26: 10962 | BG26: 12260 | BH26: 21253 | BI26: 26509 | BJ26: 29580 | BK26: 31389 | BL26: 34214 | BM26: 41950 | BN26: 42000 | BO26: 42000 | BP26: 42000 | BQ26: 42000 | BR26: 42000 | BS26: 285000 | BT26: 1374731 | BU26: 1400000 | BV26: 1500000
E27: اختلاف تورم ایران و امریکا | F27: =F7-F14 -> 0 | G27: =G7-G14 -> 8.3644348 | H27: =H7-H14 -> 2.0918402 | I27: =I7-I14 -> -0.47745278 | J27: =J7-J14 -> -0.86781981 | K27: =K7-K14 -> 2.535578 | L27: =L7-L14 -> 0.56920557 | M27: =M7-M14 -> -3.4032239 | ... BR27: =BR7-BR14 -> 36.5 | BS27: 32 | BT27: 70 | BU27: 84 | BV27: 94
E28: اختلاف رشد نقدینگی ایران و امریکا | F28: =F9-F16 -> 0 | H28: =H9-H16 -> 1.5422868 | I28: =I9-I16 -> 16.739956 | J28: =J9-J16 -> 10.025584 | K28: =K9-K16 -> 7.0010019 | L28: =L9-L16 -> 6.3322199 | M28: =M9-M16 -> 9.5395684 | N28: =N9-N16 -> 8.8710942 | O28: =O9-O16 -> 6.7395213 | ... BV28: =BV9-BV16 -> 37.43
E29: اختلاف رشد اقتصادی ایران با امریکا | F29: =F10-F17 -> 0 | H29: =H10-H17 -> 8.0909184 | I29: =I10-I17 -> 1.8092679 | J29: =J10-J17 -> 2.6420752 | K29: =K10-K17 -> 2.6752282 | L29: =L10-L17 -> 10.635712 | M29: =M10-M17 -> 5.0024073 | N29: =N10-N17 -> 8.7528031 | O29: =O10-O17 -> 9.6041827 | ... BV29: =BV10-BV17 -> -6.3
E30: اختلاف رشد نقدینگی با رشد اقتصادی (USA, IRI) | F30: =F28-F29 -> 0 | H30: =H28-H29 -> -6.5486315 | I30: =I28-I29 -> 14.930688 | J30: =J28-J29 -> 7.3835091 | K30: =K28-K29 -> 4.3257737 | L30: =L28-L29 -> -4.3034916 | M30: =M28-M29 -> 4.5371611 | N30: =N28-N29 -> 0.11829112 | O30: =O28-O29 -> -2.8646613 | ... BV30: =BV28-BV29 -> 43.73
A31: =#REF! -> #REF! | B31: =A32 -> 0 | C31: =B32 -> 0 | D31: =C32 -> 0 | E31: نرخ حقیقی ارز | G31: =G25*(G13/G4) -> 10307.926 | H31: =H25*(H13/H4) -> 10418.296 | I31: =I25*(I13/I4) -> 10543.187 | J31: =J25*(J13/J4) -> 10673.888 | K31: =K25*(K13/K4) -> 10810.398 | L31: =L25*(L13/L4) -> 10981.761 | M31: =M25*(M13/M4) -> 11312.869 | N31: =N25*(N13/N4) -> 11626.551 | ... BV31: =BV25*(BV13/BV4) -> 34459.234 | BW31: =BV32 -> 300556.67 | BX31: =BW32 -> 0 | BY31: =BX32 -> 0 | BZ31: =BY32 -> 0 | CA31: =BZ32 -> 0 | CB31: =CA32 -> 0 | CC31: =CB32 -> 0 | CD31: =CC32 -> 0 | ... XFD31: =XFC32 -> 0
E32: نرخ حقیقی ارز به قیمت های ثابت سال 1400 | G32: =G25*(G13/G4)*($BP$4/$BP$13) -> 89906.7 | H32: =H25*(H13/H4)*($BP$4/$BP$13) -> 90869.353 | I32: =I25*(I13/I4)*($BP$4/$BP$13) -> 91958.671 | J32: =J25*(J13/J4)*($BP$4/$BP$13) -> 93098.654 | K32: =K25*(K13/K4)*($BP$4/$BP$13) -> 94289.304 | L32: =L25*(L13/L4)*($BP$4/$BP$13) -> 95783.949 | M32: =M25*(M13/M4)*($BP$4/$BP$13) -> 98671.907 | N32: =N25*(N13/N4)*($BP$4/$BP$13) -> 101407.87 | ... BV32: =BV25*(BV13/BV4)*($BP$4/$BP$13) -> 300556.67
E33: نرخ حقیقی ارز به قیمت های ثابت سال 1381 | G33: =G25*(G13/G4)*($AW$4/$AW$13) -> 3386.3889 | H33: =H25*(H13/H4)*($AW$4/$AW$13) -> 3422.6478 | I33: =I25*(I13/I4)*($AW$4/$AW$13) -> 3463.6776 | J33: =J25*(J13/J4)*($AW$4/$AW$13) -> 3506.6157 | K33: =K25*(K13/K4)*($AW$4/$AW$13) -> 3551.4622 | L33: =L25*(L13/L4)*($AW$4/$AW$13) -> 3607.7589 | M33: =M25*(M13/M4)*($AW$4/$AW$13) -> 3716.5356 | N33: =N25*(N13/N4)*($AW$4/$AW$13) -> 3819.5871 | ... BV33: =BV25*(BV13/BV4)*($AW$4/$AW$13) -> 11320.644
E34: نرخ حقیقی ارز به قیمت های ثابت سال 1402 | G34: =G25*(G13/G4)*($BR$4/$BR$13) -> 165775.59 | H34: =H25*(H13/H4)*($BR$4/$BR$13) -> 167550.59 | I34: =I25*(I13/I4)*($BR$4/$BR$13) -> 169559.14 | J34: =J25*(J13/J4)*($BR$4/$BR$13) -> 171661.11 | K34: =K25*(K13/K4)*($BR$4/$BR$13) -> 173856.51 | L34: =L25*(L13/L4)*($BR$4/$BR$13) -> 176612.43 | M34: =M25*(M13/M4)*($BR$4/$BR$13) -> 181937.42 | N34: =N25*(N13/N4)*($BR$4/$BR$13) -> 186982.16 | ... BV34: =BV25*(BV13/BV4)*($BR$4/$BR$13) -> 554185.16
E35: نرخ ارز (ppp)- سال پایه 1339 | G35: =$G$25*((G6/$G$6)/(G13/$G$13)) -> 76 | H35: =$G$25*((H6/$G$6)/(H13/$G$13)) -> 77.572957 | I35: =$G$25*((I6/$G$6)/(I13/$G$13)) -> 77.20697 | J35: =$G$25*((J6/$G$6)/(J13/$G$13)) -> 76.545157 | K35: =$G$25*((K6/$G$6)/(K13/$G$13)) -> 78.46151 | L35: =$G$25*((L6/$G$6)/(L13/$G$13)) -> 78.901149 | M35: =$G$25*((M6/$G$6)/(M13/$G$13)) -> 76.294557 | N35: =$G$25*((N6/$G$6)/(N13/$G$13)) -> 75.422151 | ... BV35: =$G$25*((BV6/$G$6)/(BV13/$G$13)) -> 264069.82
E36: نرخ ارز (ppp)- سال پایه 1357 | G36: =$Y$25*((G6/$Y$6)/(G13/$Y$13)) -> 74.800417 | H36: =$Y$25*((H6/$Y$6)/(H13/$Y$13)) -> 76.348546 | I36: =$Y$25*((I6/$Y$6)/(I13/$Y$13)) -> 75.988336 | J36: =$Y$25*((J6/$Y$6)/(J13/$Y$13)) -> 75.336969 | K36: =$Y$25*((K6/$Y$6)/(K13/$Y$13)) -> 77.223075 | L36: =$Y$25*((L6/$Y$6)/(L13/$Y$13)) -> 77.655774 | M36: =$Y$25*((M6/$Y$6)/(M13/$Y$13)) -> 75.090324 | N36: =$Y$25*((N6/$Y$6)/(N13/$Y$13)) -> 74.231689 | ... BV36: =$Y$25*((BV6/$Y$6)/(BV13/$Y$13)) -> 259901.75
E37: نرخ ارز (ppp)- سال پایه 1366 | G37: =$AH$25*(G6/$AH$6)/(G13/$AH$13) -> 306.76852 | H37: =$AH$25*(H6/$AH$6)/(H13/$AH$13) -> 313.11765 | I37: =$AH$25*(I6/$AH$6)/(I13/$AH$13) -> 311.64037 | J37: =$AH$25*(J6/$AH$6)/(J13/$AH$13) -> 308.96901 | K37: =$AH$25*(K6/$AH$6)/(K13/$AH$13) -> 316.70423 | L37: =$AH$25*(L6/$AH$6)/(L13/$AH$13) -> 318.4788 | M37: =$AH$25*(M6/$AH$6)/(M13/$AH$13) -> 307.95748 | N37: =$AH$25*(N6/$AH$6)/(N13/$AH$13) -> 304.43608 | ... AG37: =$AH$25*(AG6/$AH$6)/(AG13/$AH$13) -> 799.02342 | AH37: =$AH$25*((AH6/$AH$6)/(AH13/$AH$13)) -> 991 | AI37: =$AH$25*((AI6/$AH$6)/(AI13/$AH$13)) -> 1225.1669 | AJ37: =$AH$25*((AJ6/$AH$6)/(AJ13/$AH$13)) -> 1429.963 | AK37: =$AH$25*((AK6/$AH$6)/(AK13/$AH$13)) -> 1460.2142 | AL37: =$AH$25*(AL6/$AH$6)/(AL13/$AH$13) -> 1640.8391 | AM37: =$AH$25*((AM6/$AH$6)/(AM13/$AH$13)) -> 2003.6164 | AN37: =$AH$25*(AN6/$AH$6)/(AN13/$AH$13) -> 2358.8117 | AO37: =$AH$25*(AO6/$AH$6)/(AO13/$AH$13) -> 3021.7963 | AP37: =$AH$25*(AP6/$AH$6)/(AP13/$AH$13) -> 4398.8917 | AQ37: =$AH$25*(AQ6/$AH$6)/(AQ13/$AH$13) -> 5510.2961 | AR37: =$AH$25*(AR6/$AH$6)/(AR13/$AH$13) -> 6318.581 | AS37: =$AH$25*(AS6/$AH$6)/(AS13/$AH$13) -> 7333.6288 | AT37: =$AH$25*(AT6/$AH$6)/(AT13/$AH$13) -> 8616.9977 | AU37: =$AH$25*(AU6/$AH$6)/(AU13/$AH$13) -> 9542.2315 | ... BV37: =$AH$25*(BV6/$AH$6)/(BV13/$AH$13) -> 1065898.8
E38: نرخ ارز (ppp)- سال پایه 1370 | G38: =$AL$25*((G6/$AL$6)/(G13/$AL$13)) -> 265.51821 | H38: =$AL$25*((H6/$AL$6)/(H13/$AL$13)) -> 271.01359 | I38: =$AL$25*((I6/$AL$6)/(I13/$AL$13)) -> 269.73495 | J38: =$AL$25*((J6/$AL$6)/(J13/$AL$13)) -> 267.4228 | K38: =$AL$25*((K6/$AL$6)/(K13/$AL$13)) -> 274.11789 | L38: =$AL$25*((L6/$AL$6)/(L13/$AL$13)) -> 275.65384 | M38: =$AL$25*((M6/$AL$6)/(M13/$AL$13)) -> 266.54729 | N38: =$AL$25*((N6/$AL$6)/(N13/$AL$13)) -> 263.4994 | ... BV38: =$AL$25*((BV6/$AL$6)/(BV13/$AL$13)) -> 922570.34
E39: نرخ ارز (ppp)- سال پایه 1371 | G39: =$AM$25*((G6/$AM$6)/(G13/$AM$13)) -> 229.35491 | H39: =$AM$25*((H6/$AM$6)/(H13/$AM$13)) -> 234.10182 | I39: =$AM$25*((I6/$AM$6)/(I13/$AM$13)) -> 232.99733 | J39: =$AM$25*((J6/$AM$6)/(J13/$AM$13)) -> 231.0001 | K39: =$AM$25*((K6/$AM$6)/(K13/$AM$13)) -> 236.78332 | L39: =$AM$25*((L6/$AM$6)/(L13/$AM$13)) -> 238.11007 | M39: =$AM$25*((M6/$AM$6)/(M13/$AM$13)) -> 230.24383 | N39: =$AM$25*((N6/$AM$6)/(N13/$AM$13)) -> 227.61106 | ... BV39: =$AM$25*((BV6/$AM$6)/(BV13/$AM$13)) -> 796917.23
E40: نرخ ارز (ppp)- سال پایه 1381 | G40: =$AW$25*((G6/$AW$6)/(G13/$AW$13)) -> 210.92217 | H40: =$AW$25*((H6/$AW$6)/(H13/$AW$13)) -> 215.28758 | I40: =$AW$25*((I6/$AW$6)/(I13/$AW$13)) -> 214.27186 | J40: =$AW$25*((J6/$AW$6)/(J13/$AW$13)) -> 212.43514 | K40: =$AW$25*((K6/$AW$6)/(K13/$AW$13)) -> 217.75358 | L40: =$AW$25*((L6/$AW$6)/(L13/$AW$13)) -> 218.9737 | M40: =$AW$25*((M6/$AW$6)/(M13/$AW$13)) -> 211.73965 | N40: =$AW$25*((N6/$AW$6)/(N13/$AW$13)) -> 209.31847 | ... BV40: =$AW$25*((BV6/$AW$6)/(BV13/$AW$13)) -> 732870.79
E41: نرخ ارز (ppp)- سال پایه 1390 | G41: =$BF$25*((G6/$BF$6)/((G13/$BF$13))) -> 115.566 | H41: =$BF$25*((H6/$BF$6)/((H13/$BF$13))) -> 117.95784 | I41: =$BF$25*((I6/$BF$6)/((I13/$BF$13))) -> 117.40132 | J41: =$BF$25*((J6/$BF$6)/((J13/$BF$13))) -> 116.39496 | K41: =$BF$25*((K6/$BF$6)/((K13/$BF$13))) -> 119.30898 | L41: =$BF$25*((L6/$BF$6)/((L13/$BF$13))) -> 119.9775 | M41: =$BF$25*((M6/$BF$6)/((M13/$BF$13))) -> 116.0139 | N41: =$BF$25*((N6/$BF$6)/((N13/$BF$13))) -> 114.68732 | ... BV41: =$BF$25*((BV6/$BF$6)/((BV13/$BF$13))) -> 401545.95
E42: نرخ ارز (ppp)- سال پایه 1369 | G42: =$AK$25*((G4/$AK$4)/(G13/$AK$13)) -> 254.31026 | H42: =$AK$25*((H4/$AK$4)/(H13/$AK$13)) -> 251.61614 | I42: =$AK$25*((I4/$AK$4)/(I13/$AK$13)) -> 248.63557 | J42: =$AK$25*((J4/$AK$4)/(J13/$AK$13)) -> 245.59105 | K42: =$AK$25*((K4/$AK$4)/(K13/$AK$13)) -> 242.48982 | L42: =$AK$25*((L4/$AK$4)/(L13/$AK$13)) -> 238.70593 | M42: =$AK$25*((M4/$AK$4)/(M13/$AK$13)) -> 231.71941 | N42: =$AK$25*((N4/$AK$4)/(N13/$AK$13)) -> 225.46768 | ... BV42: =$AK$25*((BV4/$AK$4)/(BV13/$AK$13)) -> 2098659.5
E43: نرخ ارز (ppp)- سال پایه 1366 | G43: =$AH$25*((G4/$AH$4)/(G13/$AH$13)) -> 253.82333 | H43: =$AH$25*((H4/$AH$4)/(H13/$AH$13)) -> 251.13437 | I43: =$AH$25*((I4/$AH$4)/(I13/$AH$13)) -> 248.1595 | J43: =$AH$25*((J4/$AH$4)/(J13/$AH$13)) -> 245.12082 | K43: =$AH$25*((K4/$AH$4)/(K13/$AH$13)) -> 242.02552 | L43: =$AH$25*((L4/$AH$4)/(L13/$AH$13)) -> 238.24888 | M43: =$AH$25*((M4/$AH$4)/(M13/$AH$13)) -> 231.27574 | N43: =$AH$25*((N4/$AH$4)/(N13/$AH$13)) -> 225.03597 | ... BV43: =$AH$25*((BV4/$AH$4)/(BV13/$AH$13)) -> 2094641.2
E44: نرخ ارز (ppp)- سال پایه 1378 | G44: =$AT$25*((G4/$AT$4)/(G13/$AT$13)) -> 261.4473 | H44: =$AT$25*((H4/$AT$4)/(H13/$AT$13)) -> 258.67758 | I44: =$AT$25*((I4/$AT$4)/(I13/$AT$13)) -> 255.61336 | J44: =$AT$25*((J4/$AT$4)/(J13/$AT$13)) -> 252.4834 | K44: =$AT$25*((K4/$AT$4)/(K13/$AT$13)) -> 249.29513 | L44: =$AT$25*((L4/$AT$4)/(L13/$AT$13)) -> 245.40505 | M44: =$AT$25*((M4/$AT$4)/(M13/$AT$13)) -> 238.22246 | N44: =$AT$25*((N4/$AT$4)/(N13/$AT$13)) -> 231.79527 | ... BV44: =$AT$25*((BV4/$AT$4)/(BV13/$AT$13)) -> 2157557
...

Sheet Macro Data
F1: گزارش سری‌های زمانی
G2: شاخص کل | I2: شاخص کل | J2: شاخص کل | Q2: عنوان متغیر: تولید ناخالص داخلی به قیمت پایه | R2: مسیر در درختواره: حساب های ملی/ حساب های ملی بر اساس سال پایه (100=1400)/ تولید(درآمد) ناخالص ملی بر حسب فعالیت های اقتصادی(به قیمت های جاری) | S2: در نظام حساب‌های ملی، تولید ناخالص داخلی به قیمت بازار عبارت است از ارزش بازار کلیه کالاها و خدماتی که در قلمرو داخلی اقتصاد توسط تولیدکنندگان مقیم تولید می‌شوند. با کسر کردن خالص مالیات‌های غیر مستقیم (یا خالص مالیات بر محصول) از تولید ناخالص داخلی به قیمت بازار، تولید ناخالص داخلی به قیمت پایه به دست می‌آید. خالص مالیات‌های غیر مستقیم برابر است با مالیات‌های غیر مستقیم منهای کمک‌های دولت به تولید کنندگان (یارانه‌ها). تولید ناخالص داخلی را می‌توان به سه روش تولید، هزینه و درآمد برآورد نمود. براساس روش تولید، تولید ناخالص داخلی به قیمت پایه برابر است با مجموع ارزش افزوده ناخالص ایجاد شده توسط کلیه تولیدکنندگان مقیم در قلمرو داخلی اقتصاد به قیمت پایه. ارزش افزوده ناخالص به قیمت پایه برابر است با ارزش ستانده به قیمت پایه منهای مصرف واسطه به قیمت خریداران. آمار تواتر سالانه آن از سال 1390 قابل گزارش‌گیری است. | T2: ارزش افزوده رشته فعاليت‌هاي اقتصادي كشور به قيمت‌هاي ثابت در دوره 98-1340 (سال پايه:1390)-(ميليارد ريال)- مرکز آمار
G3: شاخص هاي قيمت/ شاخص بهاي کالاها و خدمات مصرفي/ شاخص بهاي کالاها و خدمات مصرفي(100=1395) | H3: تورم_ شهری_ بانک مرکزی | I3: شاخص هاي قيمت/ شاخص بهاي کالاها و خدمات مصرفي/ شاخص بهاي کالاها و خدمات مصرفي (100=1390) | J3: شاخص هاي قيمت/ شاخص بهاي کالاها و خدمات مصرفي/ شاخص بهاي کالاها و خدمات مصرفي(100=1400) | N3: سال | O3: شاخص بهای کالاها و خدمات مصرفی - خانوارهای شهری-(1395=100)- | P3: نرخ تورم | T3: محصول ناخالص داخلي ( به قيمت بازار ) | U3: محصول ناخالص داخلي بدون نفت ( به قيمت بازار ) | V3: رشد اقتصادی با نفت | W3: رشد اقتصادی بدون نفت
F4: 1338 | H4: 13 | I4: 0.1 | N4: 1315 | O4: 0.004 | P4: -.-
F5: 1339 | H5: 7.9 | I5: 0.1 | N5: 1316 | O5: 0.004 | P5: 21.2
F6: 1340 | H6: 1.6 | I6: 0.1 | N6: 1317 | O6: 0.004 | P6: 8.8 | T6: 1057017.1 | U6: 1057017.1
F7: 1341 | H7: 0.9 | I7: 0.1 | N7: 1318 | O7: 0.004 | P7: 8 | T7: 1165380.1 | U7: 1165380.1
F8: 1342 | H8: 1 | I8: 0.1 | N8: 1319 | O8: 0.004 | P8: 13.8 | T8: 1263309.9 | U8: 1263309.9
F9: 1343 | H9: 4.5 | I9: 0.1 | N9: 1320 | O9: 0.008 | P9: 49.5 | T9: 1404074.2 | U9: 1404074.2
F10: 1344 | H10: 0.3 | I10: 0.1 | M10: رشد تولید | N10: 1321 | O10: 0.012 | P10: 96.2 | T10: 1590778.8 | U10: 1590778.8
F11: 1345 | H11: 0.8 | I11: 0.1 | L11: =(T16/T6-1)*100 -> 234.70317 | M11: دهه 40 | N11: 1322 | O11: 0.028 | P11: 110.5 | T11: 1782032 | U11: 1782032
F12: 1346 | H12: 0.8 | I12: 0.1 | L12: =(T26/T16-1)*100 -> -37.463566 | M12: دهه 50 | N12: 1323 | O12: 0.028 | P12: 2.7 | T12: 2010388.9 | U12: 2010388.9
F13: 1347 | H13: 1.5 | I13: 0.1 | L13: =(T36/T26-1)*100 -> 72.223864 | M13: دهه 60 | N13: 1324 | O13: 0.024 | P13: -14.4 | T13: 2296958.9 | U13: 2296958.9
F14: 1348 | H14: 3.6 | I14: 0.1 | L14: =(T46/T36-1)*100 -> 20.147683 | M14: دهه 70 | N14: 1325 | O14: 0.02 | P14: -11.5 | T14: 2683584.4 | U14: 2683584.4
F15: 1349 | H15: 1.5 | I15: 0.1 | L15: =(T56/T46-1)*100 -> 49.993141 | M15: دهه 80 | N15: 1326 | O15: 0.024 | P15: 6.6 | T15: 2908296.8 | U15: 2908296.8
F16: 1350 | H16: 5.5 | I16: 0.1 | L16: =(T63/T56-1)*100 -> 9.1881498 | M16: 90-97 | N16: 1327 | O16: 0.024 | P16: 11.1 | T16: 3537869.9 | U16: 3537869.9
F17: 1351 | H17: 6.3 | I17: 0.2 | L17: =(T69/T63-1)*100 -> 19.167582 | M17: 97-1403 | N17: 1328 | O17: 0.028 | P17: 2.3 | T17: 4048210.4 | U17: 4048210.4
F18: 1352 | H18: 11.2 | I18: 0.2 | N18: 1329 | O18: 0.02 | P18: -17.2 | T18: 4566216.3 | U18: 4566216.3
F19: 1353 | H19: 15.5 | I19: 0.2 | N19: 1330 | O19: 0.024 | P19: 8.3 | T19: 4882093.8 | U19: 4882093.8
F20: 1354 | H20: 9.9 | I20: 0.2 | N20: 1331 | O20: 0.024 | P20: 7.2 | T20: 4608071.7 | U20: 4608071.7
F21: 1355 | H21: 16.6 | I21: 0.3 | N21: 1332 | O21: 0.028 | P21: 9.2 | T21: 5261669.2 | U21: 5261669.2
F22: 1356 | H22: 25.1 | I22: 0.3 | N22: 1333 | O22: 0.032 | P22: 15.9 | T22: 4994950.8 | U22: 4994950.8
F23: 1357 | H23: 10 | I23: 0.3 | N23: 1334 | O23: 0.032 | P23: 1.7 | T23: 3683448.1 | U23: 3683448.1
F24: 1358 | H24: 11.4 | I24: 0.4 | N24: 1335 | O24: 0.036 | P24: 8.8 | T24: 3243925.6 | U24: 3243925.6
F25: 1359 | H25: 23.5 | I25: 0.5 | N25: 1336 | O25: 0.036 | P25: 4.4 | T25: 2359032.2 | U25: 2359032.2
F26: 1360 | H26: 22.8 | I26: 0.6 | N26: 1337 | O26: 0.036 | P26: 1 | T26: 2212457.7 | U26: 2212457.7
F27: 1361 | H27: 19.2 | I27: 0.7 | N27: 1338 | O27: 0.044 | P27: 13 | T27: 2900881.4 | U27: 2900881.4
F28: 1362 | H28: 14.8 | I28: 0.8 | N28: 1339 | O28: 0.048 | P28: 7.9 | T28: 3099718.4 | U28: 3099718.4
F29: 1363 | H29: 10.4 | I29: 0.9 | N29: 1340 | O29: 0.048 | P29: 1.6 | T29: 2965972.3 | U29: 2965972.3
... F34: 1368 | H34: 17.4 | I34: 2.2 | N34: 1345 | O34: 0.052 | P34: 0.8 | T34: 2977222.7 | U34: 2977222.7
F35: 1369 | G35: 1 | H35: 9 | I35: 2.45344 | N35: 1346 | O35: 0.052 | P35: 0.8 | T35: 3355192.2 | U35: 3355192.2
F36: 1370 | G36: 1.2 | H36: 20.7 | I36: 2.95856 | N36: 1347 | O36: 0.052 | P36: 1.5 | T36: 3810380.1 | U36: 3810380.1
F37: 1371 | G37: 1.5 | H37: 24.4 | I37: 3.68016 | N37: 1348 | O37: 0.052 | P37: 3.6 | T37: 3923017.1 | U37: 3923017.1
F38: 1372 | G38: 1.8 | H38: 22.9 | I38: 4.51 | N38: 1349 | O38: 0.056 | P38: 1.5 | T38: 4107256.1 | U38: 4107256.1
F39: 1373 | G39: 2.5 | H39: 35.2 | I39: 6.09752 | N39: 1350 | O39: 0.056 | P39: 5.5 | T39: 4048920.7 | U39: 4048920.7
F40: 1374 | G40: 3.7 | H40: 49.4 | I40: 9.09216 | N40: 1351 | O40: 0.06 | P40: 6.3 | T40: 4128768.9 | U40: 4128768.9
F41: 1375 | G41: 4.5 | H41: 23.2 | I41: 11.1848 | N41: 1352 | O41: 0.069 | P41: 11.2 | T41: 4328952.5 | U41: 4328952.5
F42: 1376 | G42: 5.3 | H42: 17.3 | I42: 13.1 | N42: 1353 | O42: 0.077 | P42: 15.5 | T42: 4207604.5 | U42: 4207604.5
F43: 1377 | G43: 6.3 | H43: 18.1 | I43: 15.5 | N43: 1354 | O43: 0.085 | P43: 9.9 | T43: 4297854.3 | U43: 4297854.3
F44: 1378 | G44: 7.5 | H44: 20.1 | I44: 18.6 | N44: 1355 | O44: 0.101 | P44: 16.6 | T44: 4279479.4 | U44: 4279479.4
...

Sheet Sheet1
E4: 1390 | F4: 21.5 | G4: 14
E5: 1391 | F5: 30.5 | G5: 13
E6: 1392 | F6: 34.7 | G6: 12
E7: 1393 | F7: 15.6 | G7: 11
E8: 1394 | F8: 11.9 | G8: 10
E9: 1395 | F9: 9 | G9: 9
E10: 1396 | F10: 9.6 | G10: 8
E11: 1397 | F11: 31.2 | G11: 7
E12: 1398 | F12: 41.2 | G12: 6
E13: 1399 | F13: 47.1 | G13: 5
E14: 1400 | F14: 46.2 | G14: 4
E15: 1401 | F15: 53.1 | G15: 3
... E17: 1403 | F17: 35.8 | G17: 1

Sheet monthly-yearly
B1: منبع: بانک مرکزی
B2: سال | C2: نرخ رسمی (ريال) | D2: نرخ بازار غیر رسمی (ريال) | E2: نرخ بازار غیر رسمی (ريال) | F2: رشد نرخ غیررسمی | G2: رشد نیما | H2: رشد نرخ غیررسمی | I2: رشد نیما | J2: متوسط نرخ ارز غیر رسمی در دهه های مختلف
B3: 1338 | C3: 76 | D3: 76
B4: 1339 | C4: 76 | D4: 76 | F4: =D4/D3 -> 1 | H4: =D4/D3-1 -> 0 | BV4: 0.25335806 | BW4: 0.03964503 | BX4: 3.6444114 | BY4: 0.25237763 | BZ4: 1.6853513 | CA4: -0.38383717 | CB4: #DIV/0!
B5: 1340 | C5: 76 | D5: 76 | F5: =D5/D4 -> 1 | H5: =D5/D4-1 -> 0
B6: 1341 | C6: 76 | D6: 76 | F6: =D6/D5 -> 1 | H6: =D6/D5-1 -> 0
B7: 1342 | C7: 76 | D7: 76 | F7: =D7/D6 -> 1 | H7: =D7/D6-1 -> 0 | K7: تحولات رشد میانگین سالانه متغیرها طی دوره های مختلف | X7: 40 | Y7: 50 | Z7: 60 | AA7: 70 | AB7: 80 | AC7: 90-97 | AD7: 98-403
B8: 1343 | C8: 76 | D8: 76 | F8: =D8/D7 -> 1 | H8: =D8/D7-1 -> 0 | K8: 1397 الی 1403 | L8: 90-97 | M8: دهه 80 | N8: دهه 70 | O8: دهه 60 | P8: دهه 50 | Q8: دهه 40 | R8: متغیر | W8: صادرات غیرنفتی | X8: 1.7 | Y8: 5.95785 | Z8: 7.276 | AA8: 34.88226 | AB8: 132.55231 | AC8: 284.20774 | AD8: 266.84423
B9: 1344 | C9: 76 | D9: 76 | F9: =D9/D8 -> 1 | H9: =D9/D8-1 -> 0 | K9: =AVERAGE(D62:D67) -> 264653.6 | L9: =AVERAGE(D55:D64) -> 67703.3 | M9: =AVERAGE(D45:D54) -> 9085.8 | N9: =AVERAGE(D35:D44) -> 4385.62 | O9: =AVERAGE(D26:D35) -> 873.26 | P9: =AVERAGE(D16:D25) -> 112.6 | Q9: =AVERAGE(D5:D15) -> 76 | R9: میانگین نرخ ارز در طی دوره (ریال) | Y9: =Y8/X8-1 -> 2.5046176 | Z9: =Z8/Y8-1 -> 0.22124592 | AA9: =AA8/Z8-1 -> 3.7941534 | AB9: =AB8/AA8-1 -> 2.799992 | AC9: =AC8/AB8-1 -> 1.1441176 | AD9: =AD8/AC8-1 -> -0.061094435
B10: 1345 | C10: 76 | D10: 76 | F10: =D10/D9 -> 1 | H10: =D10/D9-1 -> 0 | K10: =GEOMEAN(F62:F67)-1 -> #REF! | L10: =GEOMEAN(F55:F61)-1 -> 0.21083864 | M10: =GEOMEAN(F45:F54)-1 -> 0.0268814 | N10: =GEOMEAN(F35:F44)-1 -> 0.19130153 | O10: =GEOMEAN(F25:F34)-1 -> 0.21587715 | P10: =GEOMEAN(F15:F24)-1 -> 0.1015942 | Q10: 0 | R10: میانگین هندسی رشد
B11: 1346 | C11: 76 | D11: 76 | F11: =D11/D10 -> 1 | H11: =D11/D10-1 -> 0 | K11: =STDEV(D62:D67) -> 152917.89 | L11: =STDEV(D55:D61) -> 8786.2516 | M11: =STDEV(D45:D54) -> 867.25926 | N11: =STDEV(D35:D44) -> 2657.2141 | O11: =STDEV(D25:D34) -> 377.04991 | P11: =STDEV(D15:D24) -> 44.107948 | Q11: =STDEV(D5:D14) -> 0 | R11: انحراف معیار سالانه نرخ دلار در بازار غیررسمی (ریال) | X11: مجموع درآمدهای نفتی دهه 40 | Y11: 11.65 | Z11: 162.7
B12: 1347 | C12: 76 | D12: 76 | F12: =D12/D11 -> 1 | H12: =D12/D11-1 -> 0 | K12: =K11/K9 -> 0.57780394 | L12: =L11/L9 -> 0.12977583 | M12: =M11/M9 -> 0.095452163 | N12: =N11/N9 -> 0.60589247 | O12: =O11/O9 -> 0.4317728 | P12: =P11/P9 -> 0.39172245 | Q12: =Q11/Q9 -> 0 | R12: انحراف معیار سالانه نرخ دلار در بازار غیررسمی (درصد- نسبت به متوسط نرخ سال) | Z12: =Z11/Y11 -> 13.965665
B13: 1348 | C13: 76 | D13: 76 | F13: =D13/D12 -> 1 | H13: =D13/D12-1 -> 0 | K13: =GEOMEAN([1]Data!#REF!)-1 -> #REF! | L13: =GEOMEAN([1]Data!#REF!)-1 -> #REF! | M13: =GEOMEAN([1]Data!#REF!)-1 -> #REF! | N13: =GEOMEAN([1]Data!#REF!)-1 -> #REF! | O13: =GEOMEAN([1]Data!#REF!)-1 -> #REF! | P13: =GEOMEAN([1]Data!#REF!)-1 -> #REF! | Q13: =GEOMEAN([1]Data!#REF!)-1 -> #REF! | R13: میانگین سالانه حباب ارز (ارز آزاد با نرخ ppp)
B14: 1349 | C14: 76 | D14: 76 | F14: =D14/D13 -> 1 | H14: =D14/D13-1 -> 0 | K14: 97063.9 | L14: 5012 | M14: 886 | N14: 2557 | Q14: =STDEV(D5:D14) -> 0 | R14: انحراف معیار نرخ دلار در بازار غیررسمی (ریال)-اعلامی بانک مرکزی
B15: 1350 | C15: 76 | D15: 76 | F15: =D15/D14 -> 1 | H15: =D15/D14-1 -> 0 | K15: 4.3411774 | L15: 6.6192512 | M15: 0.33766562 | N15: 4.72525 | O15: 4.2307407 | P15: 1.6315789 | Q15: 0 | R15: رشد تجمعی نرخ ارز (درصد)
B16: 1351 | C16: 69 | D16: 69 | F16: =D16/D15 -> 0.90789474 | H16: =D16/D15-1 -> -0.092105263 | K16: 4.1542392 | L16: 2.1714258 | M16: 2.4577836 | N16: 6.0909091 | O16: 3.3345906 | P16: 2.3928571 | Q16: 0.16666667 | R16: تورم تجمعی (درصد) | W16: 0.2081597 | X16: 0.072143502 | Y16: 0.53800559 | Z16: 0.21705812 | AA16: 0.31984475 | AB16: -0.10323135 | AC16: 1.6667579
B17: 1352 | C17: 68 | D17: 68 | F17: =D17/D16 -> 0.98550725 | H17: =D17/D16-1 -> -0.014492754 | K17: 3.0603112 | L17: 4.3149946 | M17: 8.1866044 | N17: 7.7097902 | O17: 3.4230769 | P17: 13.533945 | Q17: 3.3696185 | R17: رشد تجمعی نقدینگی (درصد) | W17: 0.9116203 | X17: -0.52161326 | Y17: 3.4754153 | Z17: 0.55852887 | AA17: 0.69441567 | AB17: 0.72881064 | AC17: #DIV/0!
B18: 1353 | C18: 68 | D18: 68 | F18: =D18/D17 -> 1 | H18: =D18/D17-1 -> 0 | K18: 0.9116203 | L18: -0.52161326 | M18: 3.4754153 | N18: 0.55852887 | O18: 0.69441567 | P18: 0.72881064 | Q18: 5.52 | R18: رشد صادرات نفت و گاز ومیعانات (درصد)
B19: 1354 | C19: 68 | D19: 68 | F19: =D19/D18 -> 1 | H19: =D19/D18-1 -> 0 | K19: 0.19167582 | L19: 0.091881498 | M19: 0.49993141 | N19: 0.20147683 | O19: 0.72223864 | P19: -0.37463566 | Q19: 2.3470317 | R19: رشد تولید ناخالص داخلی
B20: 1355 | C20: 71 | D20: 71 | F20: =D20/D19 -> 1.0441176 | H20: =D20/D19-1 -> 0.044117647 | K20: 0.25335806 | L20: 0.03964503 | M20: 3.6444114 | N20: 0.25237763 | O20: 1.6853513 | P20: -0.38383717 | Q20: 2.99 | R20: رشد صادرات غیرنفتی
B21: 1356 | C21: 71 | D21: 71 | F21: =D21/D20 -> 1 | H21: =D21/D20-1 -> 0
B22: 1357 | C22: 70 | D22: 100 | F22: =D22/D21 -> 1.4084507 | H22: =D22/D21-1 -> 0.4084507
B23: 1358 | C23: 70 | D23: 141 | F23: =D23/D22 -> 1.41 | H23: =D23/D22-1 -> 0.41
B24: 1359 | C24: 71 | D24: 200 | F24: =D24/D23 -> 1.4184397 | H24: =D24/D23-1 -> 0.41843972
B25: 1360 | C25: 80 | D25: 270 | F25: =D25/D24 -> 1.35 | H25: =D25/D24-1 -> 0.35
B26: 1361 | C26: 84 | D26: 350 | F26: =D26/D25 -> 1.2962963 | H26: =D26/D25-1 -> 0.2962963
B27: 1362 | C27: 87 | D27: 450 | F27: =D27/D26 -> 1.2857143 | H27: =D27/D26-1 -> 0.28571429
B28: 1363 | C28: 92 | D28: 580 | F28: =D28/D27 -> 1.2888889 | H28: =D28/D27-1 -> 0.28888889
B29: 1364 | C29: 88 | D29: 614 | F29: =D29/D28 -> 1.0586207 | H29: =D29/D28-1 -> 0.05862069
B30: 1365 | C30: 77 | D30: 742 | F30: =D30/D29 -> 1.2084691 | H30: =D30/D29-1 -> 0.20846906
B31: 1366 | C31: 70 | D31: 991 | F31: =D31/D30 -> 1.3355795 | H31: =D31/D30-1 -> 0.33557951
B32: 1367 | C32: 69 | D32: 966 | F32: =D32/D31 -> 0.97477296 | H32: =D32/D31-1 -> -0.025227043
... B34: 1369 | C34: 66.9 | D34: 1412.3 | F34: =D34/D33 -> 1.1699942 | H34: =D34/D33-1 -> 0.1699942
B35: 1370 | C35: 67.8 | D35: 1420.2 | F35: =D35/D34 -> 1.0055937 | H35: =D35/D34-1 -> 0.0055937124 | K35: تورم | P35: بیشتر رشد میانگین سالانه نرخ ارز | S35: 234.70317
B36: 1371 | C36: 1458.5 | D36: 1498 | F36: =D36/D35 -> 1.054781 | H36: =D36/D35-1 -> 0.054781017 | K36: سال میلادی | L36: سال شمسی | M36: تورم شهری ایران | O36: 1397 | P36: 1.5555089 | S36: -37.463566
B37: 1372 | C37: 1653 | D37: 1806 | F37: =D37/D36 -> 1.2056075 | H37: =D37/D36-1 -> 0.20560748 | K37: 2000 | L37: 1379 | M37: 12.292359 | O37: 1391 | P37: 0.92062205 | S37: 72.223864
B38: 1373 | C38: 1750 | D38: 2635 | F38: =D38/D37 -> 1.4590255 | H38: =D38/D37-1 -> 0.45902547 | K38: 2001 | L38: 1380 | M38: 11.538462 | O38: 1399 | P38: 0.77117312 | S38: 20.147683
B39: 1374 | C39: 1750 | D39: 4036 | F39: =D39/D38 -> 1.5316888 | H39: =D39/D38-1 -> 0.5316888 | K39: 2002 | L39: 1381 | M39: 13.225475 | O39: 1374 | P39: 0.5316888 | S39: 49.993141
B40: 1375 | C40: 1754 | D40: 4446 | F40: =D40/D39 -> 1.1015857 | H40: =D40/D39-1 -> 0.10158573 | K40: 2003 | L40: 1382 | M40: 13.896724 | O40: 1402 | P40: 0.48883659 | S40: 9.1881498
B41: 1376 | C41: 1755 | D41: 4782 | F41: =D41/D40 -> 1.0755735 | H41: =D41/D40-1 -> 0.075573549 | K41: 2004 | L41: 1383 | M41: 14.6115 | O41: 1373 | P41: 0.45902547 | S41: 19.167582
...

Sheet daily
C1: نرخ روزانه دلار در دهه 80 | F1: نرخ روزانه دلار 90-95 | I1: نرخ روزانه دلار 95-1400 | L1: نرخ روزانه دلار 1400 به بعد (منبع: بورس ویو)
A2: تاریخ میلادی | C2: تاریخ شمسی | D2: نرخ غیررسمی ارز در تهران | F2: تاریخ شمسی | G2: نرخ غیررسمی ارز در تهران | I2: تاریخ شمسی | J2: نرخ غیررسمی ارز در تهران | L2: تاریخ شمسی | M2: نرخ غیررسمی ارز در تهران | O2: تاریخ (ماه) | P2: نرخ متوسط ماهانه دلار | Q2: رشد ماهانه | R2: میانگین رشد هر ماه | S2: چند برابر شدن ماهانه | U2: رشد متوسط ماهانه از سال 90-1403 | AD2: تاریخ (سال) | AE2: نرخ متوسط سالانه دار آزاد
A3: 2002/03/21 | C3: 1381/01/01 | F3: 1390/01/01 | G3: 10364 | I3: 1395/01/01 | L3: 1400/01/01 | O3: 1390:1 | P3: =AVERAGE(G3:G33) -> 10857.034 | Q3: =((P3/AVERAGE(D3261:D3289))-1)*100 -> 5.2516514 | R3: =GEOMEAN(S3,S15,S27,S39,S51,S63,S75,S87,S99,S111,S123,S135,S147,S159)-1 -> 0.027081433 | S3: =(P3/AVERAGE(D3261:D3289)) -> 1.0525165 | T3: فروردین | U3: =R3 -> 0.027081433 | V3: دلار دولتی (روزانه/ ریال) | AD3: 1381
A4: 2002/03/22 | C4: 1381/01/02 | F4: 1390/01/02 | G4: 10364 | I4: 1395/01/02 | L4: 1400/01/02 | O4: 1390:2 | P4: =AVERAGE(G34:G64) -> 11524.4 | Q4: =(P4/P3-1)*100 -> 6.146849 | R4: =GEOMEAN(S4,S16,S28,S40,S52,S64,S76,S88,S100,S112,S124,S136,S148,S160)-1 -> 0.015288914 | S4: =(P4/P3) -> 1.0614685 | T4: اردیبهشت | U4: =R4 -> 0.015288914 | V4: Date | W4: USD | AD4: 1382
A5: 2002/03/23 | C5: 1381/01/03 | F5: 1390/01/03 | G5: 10364 | I5: 1395/01/03 | L5: 1400/01/03 | O5: 1390:3 | P5: =AVERAGE(G65:G95) -> 11999.583 | Q5: =(P5/P4-1)*100 -> 4.1232805 | R5: =GEOMEAN(S5,S17,S29,S41,S53,S65,S77,S89,S101,S113,S125,S137,S149,S161)-1 -> 0.014638708 | S5: =(P5/P4) -> 1.0412328 | T5: خرداد | U5: =R5 -> 0.014638708 | V5: 1371/01/05 | W5: 1439 | Z5: =STDEV(D3:D3289) -> 726.27953 | AA5: =STDEV(D3290:D6942) -> #DIV/0! | AD5: 1383
A6: 2002/03/24 | C6: 1381/01/04 | F6: 1390/01/04 | G6: 10364 | I6: 1395/01/04 | L6: 1400/01/04 | O6: 1390:4 | P6: =AVERAGE(G96:G126) -> 11584 | Q6: =(P6/P5-1)*100 -> -3.4633147 | R6: =GEOMEAN(S6,S18,S30,S42,S54,S66,S78,S90,S102,S114,S126,S138,S150,S162)-1 -> 0.02176665 | S6: =(P6/P5) -> 0.96536685 | T6: تیر | U6: =R6 -> 0.02176665 | V6: 1371/01/08 | W6: 1439 | AD6: 1384
A7: 2002/03/25 | C7: 1381/01/05 | D7: 7924 | F7: 1390/01/05 | G7: 10364 | I7: 1395/01/05 | L7: 1400/01/05 | O7: 1390:5 | P7: =AVERAGE(G127:G157) -> 11527.6 | Q7: =(P7/P6-1)*100 -> -0.48687845 | R7: =GEOMEAN(S7,S19,S31,S43,S55,S67,S79,S91,S103,S115,S127,S139,S151,S163)-1 -> 0.020851317 | S7: =(P7/P6) -> 0.99513122 | T7: مرداد | U7: =R7 -> 0.020851317 | V7: 1371/01/09 | W7: 1439 | AD7: 1385 | AI7: بورس ویو
A8: 2002/03/26 | C8: 1381/01/06 | D8: 7924 | F8: 1390/01/06 | G8: 10384 | I8: 1395/01/06 | J8: 34680 | L8: 1400/01/06 | O8: 1390:6 | P8: =AVERAGE(G158:G188) -> 12352.8 | Q8: =(P8/P7-1)*100 -> 7.1584718 | R8: =GEOMEAN(S8,S20,S32,S44,S56,S68,S80,S92,S104,S116,S128,S140,S152,S164)-1 -> 0.041276893 | S8: =(P8/P7) -> 1.0715847 | T8: شهریور | U8: =R8 -> 0.041276893 | V8: 1371/01/10 | W8: 1439 | AA8: بیشتر رشد ماهانه از سال 1390 | AD8: 1386 | AH8: 2021-03-27 | AI8: 1400-01-07 | AJ8: 247560
A9: 2002/03/27 | C9: 1381/01/07 | D9: 7924 | F9: 1390/01/07 | G9: 10384 | I9: 1395/01/07 | J9: 34660 | L9: 1400/01/07 | M9: 251900 | O9: 1390:7 | P9: =AVERAGE(G219:G248) -> 13155 | Q9: =(P9/P8-1)*100 -> 6.4940742 | R9: =GEOMEAN(S9,S21,S33,S45,S57,S69,S81,S93,S105,S117,S129,S141,S153)-1 -> 0.051944231 | S9: =(P9/P8) -> 1.0649407 | T9: مهر | U9: =R9 -> 0.051944231 | V9: 1371/01/11 | W9: 1439 | Z9: =R3 -> 0.027081433 | AA9: فروردین | AD9: 1387 | AH9: 2021-03-28 | AI9: 1400-01-08 | AJ9: 252330
A10: 2002/03/28 | C10: 1381/01/08 | D10: 7924 | F10: 1390/01/08 | G10: 10392 | I10: 1395/01/08 | L10: 1400/01/08 | M10: 256500 | O10: 1390:8 | P10: =AVERAGE(G100:G130) -> 11525.385 | Q10: =(P10/P9-1)*100 -> -12.387802 | R10: =GEOMEAN(S10,S22,S34,S46,S58,S70,S82,S94,S106,S118,S130,S142,S154,S166)-1 -> -0.00067666676 | S10: =(P10/P9) -> 0.87612198 | T10: آبان | U10: =R10 -> -0.00067666676 | V10: 1371/01/16 | W10: 1439 | Z10: =R4 -> 0.015288914 | AA10: اردیبهشت | AD10: 1388 | AH10: 2021-03-30 | AI10: 1400-01-10 | AJ10: 252540
A11: 2002/03/29 | C11: 1381/01/09 | D11: 7924 | F11: 1390/01/09 | G11: 10394 | I11: 1395/01/09 | J11: 35130 | L11: 1400/01/09 | O11: 1390:9 | P11: =AVERAGE(G249:G278) -> 13760.833 | Q11: =(P11/P10-1)*100 -> 19.395871 | R11: =GEOMEAN(S11,S23,S35,S47,S59,S71,S83,S95,S107,S119,S131,S143,S155,S167)-1 -> 0.011088797 | S11: =(P11/P10) -> 1.1939587 | T11: آذر | U11: =R11 -> 0.011088797 | V11: 1371/01/17 | W11: 1439 | Z11: =R5 -> 0.014638708 | AA11: خرداد | AD11: 1389 | AH11: 2021-03-31 | AI11: 1400-01-11 | AJ11: 252040
A12: 2002/03/30 | C12: 1381/01/10 | D12: 7924 | F12: 1390/01/10 | G12: 10400 | I12: 1395/01/10 | J12: 34820 | L12: 1400/01/10 | M12: 258200 | O12: 1390:10 | P12: =AVERAGE(G279:G308) -> 16170.435 | Q12: =(P12/P11-1)*100 -> 17.510578 | R12: =GEOMEAN(S12,S24,S36,S48,S60,S72,S84,S96,S108,S120,S132,S144,S156,S168)-1 -> 0.026582767 | S12: =(P12/P11) -> 1.1751058 | T12: دی | U12: =R12 -> 0.026582767 | V12: 1371/01/18 | W12: 1439 | Z12: =R6 -> 0.02176665 | AA12: تیر | AD12: 1390 | AE12: =AVERAGE(P3:P14) -> 13527.51 | AH12: 2021-04-01 | AI12: 1400-01-12 | AJ12: 252100
A13: 2002/03/31 | C13: 1381/01/11 | D13: 7924 | F13: 1390/01/11 | G13: 10400 | I13: 1395/01/11 | J13: 34850 | L13: 1400/01/11 | M13: 257200 | O13: 1390:11 | P13: =AVERAGE(G309:G338) -> 18860 | Q13: =(P13/P12-1)*100 -> 16.632609 | R13: =GEOMEAN(S13,S25,S37,S49,S61,S73,S85,S97,S109,S121,S133,S145,S157,S169)-1 -> 0.050868237 | S13: =(P13/P12) -> 1.1663261 | T13: بهمن | U13: =R13 -> 0.050868237 | V13: 1371/01/19 | W13: 1439 | Z13: =R7 -> 0.020851317 | AA13: مرداد | AD13: 1391 | AE13: =AVERAGE(P15:P26) -> 26146.497 | AH13: 2021-04-03 | AI13: 1400-01-14 | AJ13: 244650
A14: 2002/04/01 | C14: 1381/01/12 | D14: 7924 | F14: 1390/01/12 | G14: 10400 | I14: 1395/01/12 | L14: 1400/01/12 | O14: 1390:12 | P14: =AVERAGE(G339:G367) -> 19013.043 | Q14: =(P14/P13-1)*100 -> 0.81147125 | R14: =GEOMEAN(S14,S26,S38,S50,S62,S74,S86,S98,S110,S122,S134,S146,S158,S170,S182)-1 -> 0.025424336 | S14: =(P14/P13) -> 1.0081147 | T14: اسفند | U14: =R14 -> 0.025424336 | V14: 1371/01/20 | W14: 1439 | Z14: =R8 -> 0.041276893 | AA14: شهریور | AD14: 1392 | AE14: =AVERAGE(P27:P38) -> 31861.737 | AH14: 2021-04-04 | AI14: 1400-01-15 | AJ14: 242720
A15: 2002/04/02 | C15: 1381/01/13 | D15: 7924 | F15: 1390/01/13 | G15: 10400 | I15: 1395/01/13 | J15: 34750 | L15: 1400/01/13 | O15: 1391:01 | P15: =AVERAGE(G368:G398) -> 18704.5 | Q15: =(P15/P14-1)*100 -> -1.622799 | S15: =(P15/P14) -> 0.98377201 | V15: 1371/01/22 | W15: 1439 | Z15: =R9 -> 0.051944231 | AA15: مهر | AD15: 1393 | AE15: =AVERAGE(P39:P50) -> 32704.493 | AH15: 2021-04-05 | AI15: 1400-01-16 | AJ15: 244050
A16: 2002/04/03 | C16: 1381/01/14 | D16: 7924 | F16: 1390/01/14 | G16: 11120 | I16: 1395/01/14 | J16: 34490 | L16: 1400/01/14 | M16: 246000 | O16: 1391:02 | P16: =AVERAGE(G399:G429) -> 16882.609 | Q16: =(P16/P15-1)*100 -> -9.7403903 | S16: =(P16/P15) -> 0.9025961 | V16: 1371/01/23 | W16: 1439 | Z16: =R10 -> -0.00067666676 | AA16: آبان | AD16: 1394 | AE16: =AVERAGE(P51:P62) -> 33595.534 | AH16: 2021-04-06 | AI16: 1400-01-17 | AJ16: 247110
A17: 2002/04/04 | C17: 1381/01/15 | F17: 1390/01/15 | G17: 11120 | I17: 1395/01/15 | J17: 34500 | L17: 1400/01/15 | M17: 249700 | O17: 1391:03 | P17: =AVERAGE(G430:G460) -> 17672.5 | Q17: =(P17/P16-1)*100 -> 4.6787278 | S17: =(P17/P16) -> 1.0467873 | V17: 1371/01/24 | W17: 1439 | Z17: =R11 -> 0.011088797 | AA17: آذر | AD17: 1395 | AE17: =AVERAGE(P63:P74) -> 36305.738 | AH17: 2021-04-07 | AI17: 1400-01-18 | AJ17: 244620
A18: 2002/04/05 | C18: 1381/01/16 | D18: 7924 | F18: 1390/01/16 | G18: 11150 | I18: 1395/01/16 | J18: 34760 | L18: 1400/01/16 | M18: 251000 | O18: 1391:04 | P18: =AVERAGE(G461:G491) -> 19298.4 | Q18: =(P18/P17-1)*100 -> 9.2001698 | S18: =(P18/P17) -> 1.0920017 | V18: 1371/01/25 | W18: 1439 | Z18: =R12 -> 0.026582767 | AA18: دی | AD18: 1396 | AE18: =AVERAGE(P75:P86) -> 40545.729 | AH18: 2021-04-08 | AI18: 1400-01-19 | AJ18: 244660
A19: 2002/04/06 | C19: 1381/01/17 | D19: 7924 | F19: 1390/01/17 | G19: 11200 | I19: 1395/01/17 | J19: 34700 | L19: 1400/01/17 | M19: 250500 | O19: 1391:05 | P19: =AVERAGE(G492:G522) -> 20433.2 | Q19: =(P19/P18-1)*100 -> 5.8802802 | S19: =(P19/P18) -> 1.0588028 | V19: 1371/01/26 | W19: 1439 | Z19: =R13 -> 0.050868237 | AA19: بهمن | AD19: 1397 | AE19: =AVERAGE(P87:P98) -> 104041.57 | AH19: 2021-04-10 | AI19: 1400-01-21 | AJ19: 241880
A20: 2002/04/07 | C20: 1381/01/18 | D20: 7924 | F20: 1390/01/18 | G20: 11250 | I20: 1395/01/18 | J20: 34650 | L20: 1400/01/18 | M20: 251500 | O20: 1391:06 | P20: =AVERAGE(G523:G553) -> 23020.417 | Q20: =(P20/P19-1)*100 -> 12.661828 | S20: =(P20/P19) -> 1.1266183 | V20: 1371/01/27 | W20: 1439 | Z20: =R14 -> 0.025424336 | AA20: اسفند | AD20: 1398 | AE20: =AVERAGE(P99:P110) -> 128346.11 | AH20: 2021-04-11 | AI20: 1400-01-22 | AJ20: 242850
A21: 2002/04/08 | C21: 1381/01/19 | D21: 7924 | F21: 1390/01/19 | I21: 1395/01/19 | J21: 34650 | L21: 1400/01/19 | M21: 248000 | O21: 1391:07 | P21: =AVERAGE(G554:G583) -> 31481.538 | Q21: =(P21/P20-1)*100 -> 36.754859 | S21: =(P21/P20) -> 1.3675486 | V21: 1371/01/29 | W21: 1439 | AD21: 1399 | AE21: =AVERAGE(P111:P122) -> 228057.07 | AH21: 2021-04-12 | AI21: 1400-01-23 | AJ21: 242960
A22: 2002/04/09 | C22: 1381/01/20 | D22: 7924 | F22: 1390/01/20 | G22: 11280 | I22: 1395/01/20 | J22: 34690 | L22: 1400/01/20 | O22: 1391:08 | P22: =AVERAGE(G584:G613) -> 31513.333 | Q22: =(P22/P21-1)*100 -> 0.10099529 | S22: =(P22/P21) -> 1.00101 | V22: 1371/01/30 | W22: 1439 | AD22: 1400 | AE22: =AVERAGE(P123:P134) -> 264772.57 | AH22: 2021-04-13 | AI22: 1400-01-24 | AJ22: 240900
A23: 2002/04/10 | C23: 1381/01/21 | D23: 7924 | F23: 1390/01/21 | G23: 11270 | I23: 1395/01/21 | J23: 34720 | L23: 1400/01/21 | M23: 248300 | O23: 1391:09 | P23: =AVERAGE(G614:G643) -> 29522.5 | Q23: =(P23/P22-1)*100 -> -6.3174318 | S23: =(P23/P22) -> 0.93682568 | V23: 1371/01/31 | W23: 1439 | AD23: 1401 | AE23: =AVERAGE(P135:P146) -> 355251.22 | AH23: 2021-04-14 | AI23: 1400-01-25 | AJ23: 242350
A24: 2002/04/11 | C24: 1381/01/22 | D24: 7924 | F24: 1390/01/22 | G24: 11250 | I24: 1395/01/22 | J24: 34700 | L24: 1400/01/22 | M24: 248000 | O24: 1391:10 | P24: =AVERAGE(G644:G673) -> 32675.652 | Q24: =(P24/P23-1)*100 -> 10.680505 | S24: =(P24/P23) -> 1.1068051 | V24: 1371/02/01 | W24: 1444 | AD24: 1402 | AE24: =AVERAGE(P147:P158) -> 517562.26 | AH24: 2021-04-15 | AI24: 1400-01-26 | AJ24: 239870
A25: 2002/04/12 | C25: 1381/01/23 | D25: 7924 | F25: 1390/01/23 | G25: 11250 | I25: 1395/01/23 | J25: 34690 | L25: 1400/01/23 | M25: 250000 | O25: 1391:11 | P25: =AVERAGE(G674:G703) -> 37010.4 | Q25: =(P25/P24-1)*100 -> 13.265987 | S25: =(P25/P24) -> 1.1326599 | V25: 1371/02/02 | W25: 1444 | AD25: 1403 | AH25: 2021-04-17 | AI25: 1400-01-28 | AJ25: 239930
A26: 2002/04/13 | C26: 1381/01/24 | D26: 7924 | F26: 1390/01/24 | G26: 11270 | I26: 1395/01/24 | J26: 34660 | L26: 1400/01/24 | M26: 248800 | O26: 1391:12 | P26: =AVERAGE(G704:G733) -> 35542.917 | Q26: =(P26/P25-1)*100 -> -3.9650567 | S26: =(P26/P25) -> 0.96034943 | V26: 1371/02/03 | W26: 1444 | AD26: 1404 | AH26: 2021-04-18 | AI26: 1400-01-29 | AJ26: 238820
A27: 2002/04/14 | C27: 1381/01/25 | D27: 7924 | F27: 1390/01/25 | G27: 11350 | I27: 1395/01/25 | J27: 34620 | L27: 1400/01/25 | M27: 249400 | O27: 1392:01 | P27: =AVERAGE(G734:G764) -> 35287.5 | Q27: =(P27/P26-1)*100 -> -0.71861482 | S27: =(P27/P26) -> 0.99281385 | V27: 1371/02/05 | W27: 1444 | AD27: 1405 | AH27: 2021-04-19 | AI27: 1400-01-30 | AJ27: 238170
A28: 2002/04/15 | C28: 1381/01/26 | D28: 7924 | F28: 1390/01/26 | I28: 1395/01/26 | L28: 1400/01/26 | M28: 249000 | O28: 1392:02 | P28: =AVERAGE(G765:G795) -> 35498 | Q28: =(P28/P27-1)*100 -> 0.59652852 | S28: =(P28/P27) -> 1.0059653 | V28: 1371/02/06 | W28: 1452 | AH28: 2021-04-20 | AI28: 1400-01-31 | AJ28: 233740 | AK28: =AVERAGE(AJ7:AJ28) -> 244088.1 | AL28: فروردین1400
A29: 2002/04/16 | C29: 1381/01/27 | D29: 7924 | F29: 1390/01/27 | G29: 11350 | I29: 1395/01/27 | J29: 34640 | L29: 1400/01/27 | O29: 1392:03 | P29: =AVERAGE(G796:G826) -> 35725.652 | Q29: =(P29/P28-1)*100 -> 0.64130986 | S29: =(P29/P28) -> 1.0064131 | V29: 1371/02/07 | W29: 1452 | AH29: 2021-04-21 | AI29: 1400-02-01 | AJ29: 233690
A30: 2002/04/17 | C30: 1381/01/28 | D30: 7924 | F30: 1390/01/28 | G30: 11350 | I30: 1395/01/28 | J30: 34550 | L30: 1400/01/28 | M30: 248300 | O30: 1392:04 | P30: =AVERAGE(G827:G857) -> 32782 | Q30: =(P30/P29-1)*100 -> -8.2396037 | S30: =(P30/P29) -> 0.91760396 | V30: 1371/02/09 | W30: 1452 | AH30: 2021-04-22 | AI30: 1400-02-02 | AJ30: 233300
A31: 2002/04/18 | C31: 1381/01/29 | D31: 7924 | F31: 1390/01/29 | G31: 11250 | I31: 1395/01/29 | J31: 34510 | L31: 1400/01/29 | M31: 245700 | O31: 1392:05 | P31: =AVERAGE(G858:G888) -> 31797.2 | Q31: =(P31/P30-1)*100 -> -3.0040876 | S31: =(P31/P30) -> 0.96995912 | V31: 1371/02/10 | W31: 1452 | AH31: 2021-04-24 | AI31: 1400-02-04 | AJ31: 233370
A32: 2002/04/19 | C32: 1381/01/30 | D32: 7924 | F32: 1390/01/30 | G32: 11200 | I32: 1395/01/30 | J32: 34640 | L32: 1400/01/30 | M32: 242000 | O32: 1392:06 | P32: =AVERAGE(G889:G919) -> 31872.917 | Q32: =(P32/P31-1)*100 -> 0.23812369 | S32: =(P32/P31) -> 1.0023812 | V32: 1371/02/12 | W32: 1452 | AH32: 2021-04-25 | AI32: 1400-02-05 | AJ32: 233390
